Workbook

Sheet 1. Master Inputs
A1: GLOBAL PLANNING PARAMETERS
A2: Parameter | B2: Value | C2: Unit
A3: Total Capital Budget | B3: 450 | C3: Lakhs
A4: Min 5km Coverage Rule | B4: 0.9 | C4: Percentage
A5: Max Utilization Cap | B5: 0.85 | C5: Percentage
A6: Planning Horizon | B6: 2 | C6: Years
A8: CHARGER SPECIFICATIONS
A9: Charger Type | B9: Setup Cost (Lakh) | C9: Daily Capacity | D9: Power Draw (kW) | E9: Revenue/Session
A10: Standard | B10: 8 | C10: 16 | D10: 40 | E10: 185
A11: Fast | B11: 15 | C11: 28 | D11: 80 | E11: 260
A14: CANDIDATE SITE DATA
A15: Site Code | B15: Site Name | C15: Fixed Setup (Lakh) | D15: Grid Limit (kW) | E15: Max Chargers | F15: Op Cost (Lakh/mo)
A16: C1 | B16: CBD Mall | C16: 70 | D16: 700 | E16: 14 | F16: 3.2
A17: C2 | B17: North Metro | C17: 48 | D17: 450 | E17: 9 | F17: 2.4
A18: C3 | B18: Tech Park | C18: 65 | D18: 800 | E18: 16 | F18: 3.5
A19: C4 | B19: University | C19: 42 | D19: 400 | E19: 8 | F19: 2.1
A20: C5 | B20: Highway Hub | C20: 55 | D20: 900 | E20: 18 | F20: 2.8
A21: C6 | B21: South Plaza | C21: 45 | D21: 500 | E21: 10 | F21: 2.3
A23: DEMAND ZONES (BASELINE)
A24: Zone Code | B24: Zone Name | C24: Baseline Sessions | D24: Peak Share | E24: 2-Yr Growth
A25: Z1 | B25: CBD | C25: 180 | D25: 0.3 | E25: 1.35
A26: Z2 | B26: Residential North | C26: 120 | D26: 0.28 | E26: 1.55
A27: Z3 | B27: Tech Corridor | C27: 220 | D27: 0.4 | E27: 1.7
A28: Z4 | B28: University | C28: 100 | D28: 0.3 | E28: 1.4
A29: Z5 | B29: Highway | C29: 160 | D29: 0.45 | E29: 1.6
A30: Z6 | B30: South Residential | C30: 140 | D30: 0.25 | E30: 1.5
A32: DISTANCE MATRIX (km)
A33: Site \ Zone | B33: Z1 | C33: Z2 | D33: Z3 | E33: Z4 | F33: Z5 | G33: Z6
A34: C1 | B34: 1 | C34: 5 | D34: 4 | E34: 3 | F34: 8 | G34: 7
A35: C2 | B35: 5 | C35: 1 | D35: 6 | E35: 4 | F35: 9 | G35: 8
A36: C3 | B36: 4 | C36: 6 | D36: 1 | E36: 4 | F36: 5 | G36: 6
A37: C4 | B37: 3 | C37: 4 | D37: 4 | E37: 1 | F37: 7 | G37: 5
A38: C5 | B38: 8 | C38: 9 | D38: 5 | E38: 7 | F38: 1 | G38: 4
A39: C6 | B39: 7 | C39: 8 | D39: 6 | E39: 5 | F39: 4 | G39: 1

Sheet Answer Report 1
A1: Microsoft Excel 16.0 Answer Report
A2: Worksheet: [El_Dorado_EV_Master.xlsx]2. Optimization Engine
A3: Report Created: 16-09-2026 14:11:40
A4: Result: Solver found a solution. All Constraints and optimality conditions are satisfied.
A5: Solver Engine
B6: Engine: Simplex LP
B7: Solution Time: 0.75 Seconds.
B8: Iterations: 7 Subproblems: 168
A9: Solver Options
B10: Max Time Unlimited, Iterations Unlimited, Precision 0.000001, Use Automatic Scaling
B11: Max Subproblems Unlimited, Max Integer Sols Unlimited, Integer Tolerance 0%, Assume NonNegative
A14: Objective Cell (Max)
B15: Cell | C15: Name | D15: Original Value | E15: Final Value
B16: $N$9 | C16: Total Profit: Net Profit | D16: 45.864 | E16: 44.568
A19: Variable Cells
B20: Cell | C20: Name | D20: Original Value | E20: Final Value | F20: Integer
B21: $C$2 | C21: CBD Mall Open Site (X_j) | D21: 0 | E21: 0 | F21: Binary
B22: $D$2 | C22: CBD Mall Standard (S_j) | D22: 0 | E22: 0 | F22: Integer
B23: $E$2 | C23: CBD Mall Fast (F_j) | D23: 0 | E23: 0 | F23: Integer
B24: $C$3 | C24: North Metro Open Site (X_j) | D24: 0 | E24: 0 | F24: Binary
B25: $D$3 | C25: North Metro Standard (S_j) | D25: 0 | E25: 0 | F25: Integer
B26: $E$3 | C26: North Metro Fast (F_j) | D26: 0 | E26: 0 | F26: Integer
B27: $C$4 | C27: Tech Park Open Site (X_j) | D27: 1 | E27: 0 | F27: Binary
B28: $D$4 | C28: Tech Park Standard (S_j) | D28: 0 | E28: 0 | F28: Integer
B29: $E$4 | C29: Tech Park Fast (F_j) | D29: 10 | E29: 0 | F29: Integer
B30: $C$5 | C30: University Open Site (X_j) | D30: 0 | E30: 1 | F30: Binary
B31: $D$5 | C31: University Standard (S_j) | D31: 0 | E31: 0 | F31: Integer
B32: $E$5 | C32: University Fast (F_j) | D32: 0 | E32: 5 | F32: Integer
... B44: $D$17 | C44: Z6 Zone Covered? (Y) | D44: 0 | E44: 1 | F44: Binary
A47: Constraints
B48: Cell | C48: Name | D48: Cell Value | E48: Formula | F48: Status | G48: Slack
B49: $D$12 | C49: Z1 Zone Covered? (Y) | D49: 1 | E49: $D$12<=$C$12 | F49: Binding | G49: 0
B50: $D$13 | C50: Z2 Zone Covered? (Y) | D50: 1 | E50: $D$13<=$C$13 | F50: Binding | G50: 0
B51: $D$14 | C51: Z3 Zone Covered? (Y) | D51: 1 | E51: $D$14<=$C$14 | F51: Binding | G51: 0
B52: $D$15 | C52: Z4 Zone Covered? (Y) | D52: 1 | E52: $D$15<=$C$15 | F52: Binding | G52: 0
B53: $D$16 | C53: Z5 Zone Covered? (Y) | D53: 1 | E53: $D$16<=$C$16 | F53: Not Binding | G53: 1
B54: $D$17 | C54: Z6 Zone Covered? (Y) | D54: 1 | E54: $D$17<=$C$17 | F54: Not Binding | G54: 1
B55: $F$19 | C55: Coverage %: Total Chargers | D55: 1 | E55: $F$19>=0.9 | F55: Not Binding | G55: 0.1
B56: $F$2 | C56: CBD Mall Total Chargers | D56: 0 | E56: $F$2<=$G$2 | F56: Binding | G56: 0
B57: $F$3 | C57: North Metro Total Chargers | D57: 0 | E57: $F$3<=$G$3 | F57: Binding | G57: 0
...

Sheet 2. Optimization Engine
A1: Site Code | B1: Site Name | C1: Open Site (X_j) | D1: Standard (S_j) | E1: Fast (F_j) | F1: Total Chargers | G1: Max Allowed | H1: Power (kW) | I1: Grid Limit | J1: CapEx (Lakh) | K1: Daily Cap | L1: Daily Rev | M1: Monthly Rev | N1: Net Profit
A2: C1 | B2: CBD Mall | C2: 0 | D2: 0 | E2: 0 | F2: =D2+E2 -> 0 | G2: ='1. Master Inputs'!E16*C2 -> 0 | H2: =(D2*'1. Master Inputs'!D10) + (E2*'1. Master Inputs'!D11) -> 0 | I2: ='1. Master Inputs'!D16*C2 -> 0 | J2: =(C2*'1. Master Inputs'!C16) + (D2*'1. Master Inputs'!B10) + (E2*'1. Master Inputs'!B11) -> 0 | K2: =(D2*'1. Master Inputs'!C10) + (E2*'1. Master Inputs'!C11) -> 0 | L2: =((D2 * '1. Master Inputs'!$C$10 * '1. Master Inputs'!$E$10) + (E2 * '1. Master Inputs'!$C$11 * '1. Master Inputs'!$E$11)) * '3. Risk Simulation'!$B$6 -> 0 | M2: =(L2*30)/100000 -> 0 | N2: =M2-('1. Master Inputs'!F1*C2) -> 0
A3: C2 | B3: North Metro | C3: 0 | D3: 0 | E3: 0 | F3: =D3+E3 -> 0 | G3: ='1. Master Inputs'!E17*C3 -> 0 | H3: =(D3*'1. Master Inputs'!D10) + (E3*'1. Master Inputs'!D11) -> 0 | I3: ='1. Master Inputs'!D17*C3 -> 0 | J3: =(C3*'1. Master Inputs'!C17) + (D3*'1. Master Inputs'!B10) + (E3*'1. Master Inputs'!B11) -> 0 | K3: =(D3*'1. Master Inputs'!C10) + (E3*'1. Master Inputs'!C11) -> 0 | L3: =((D3 * '1. Master Inputs'!$C$10 * '1. Master Inputs'!$E$10) + (E3 * '1. Master Inputs'!$C$11 * '1. Master Inputs'!$E$11)) * '3. Risk Simulation'!$B$6 -> 0 | M3: =(L3*30)/100000 -> 0 | N3: =M3-('1. Master Inputs'!F2*C3) -> 0
A4: C3 | B4: Tech Park | C4: 0 | D4: 0 | E4: 0 | F4: =D4+E4 -> 0 | G4: ='1. Master Inputs'!E18*C4 -> 0 | H4: =(D4*'1. Master Inputs'!D10) + (E4*'1. Master Inputs'!D11) -> 0 | I4: ='1. Master Inputs'!D18*C4 -> 0 | J4: =(C4*'1. Master Inputs'!C18) + (D4*'1. Master Inputs'!B10) + (E4*'1. Master Inputs'!B11) -> 0 | K4: =(D4*'1. Master Inputs'!C10) + (E4*'1. Master Inputs'!C11) -> 0 | L4: =((D4 * '1. Master Inputs'!$C$10 * '1. Master Inputs'!$E$10) + (E4 * '1. Master Inputs'!$C$11 * '1. Master Inputs'!$E$11)) * '3. Risk Simulation'!$B$6 -> 0 | M4: =(L4*30)/100000 -> 0 | N4: =M4-('1. Master Inputs'!F3*C4) -> 0
A5: C4 | B5: University | C5: 1 | D5: 0 | E5: 5 | F5: =D5+E5 -> 5 | G5: ='1. Master Inputs'!E19*C5 -> 8 | H5: =(D5*'1. Master Inputs'!D10) + (E5*'1. Master Inputs'!D11) -> 400 | I5: ='1. Master Inputs'!D19*C5 -> 400 | J5: =(C5*'1. Master Inputs'!C19) + (D5*'1. Master Inputs'!B10) + (E5*'1. Master Inputs'!B11) -> 117 | K5: =(D5*'1. Master Inputs'!C10) + (E5*'1. Master Inputs'!C11) -> 140 | L5: =((D5 * '1. Master Inputs'!$C$10 * '1. Master Inputs'!$E$10) + (E5 * '1. Master Inputs'!$C$11 * '1. Master Inputs'!$E$11)) * '3. Risk Simulation'!$B$6 -> 39312 | M5: =(L5*30)/100000 -> 11.7936 | N5: =M5-('1. Master Inputs'!F4*C5) -> 11.7936
A6: C5 | B6: Highway Hub | C6: 1 | D6: 0 | E6: 11 | F6: =D6+E6 -> 11 | G6: ='1. Master Inputs'!E20*C6 -> 18 | H6: =(D6*'1. Master Inputs'!D10) + (E6*'1. Master Inputs'!D11) -> 880 | I6: ='1. Master Inputs'!D20*C6 -> 900 | J6: =(C6*'1. Master Inputs'!C20) + (D6*'1. Master Inputs'!B10) + (E6*'1. Master Inputs'!B11) -> 220 | K6: =(D6*'1. Master Inputs'!C10) + (E6*'1. Master Inputs'!C11) -> 308 | L6: =((D6 * '1. Master Inputs'!$C$10 * '1. Master Inputs'!$E$10) + (E6 * '1. Master Inputs'!$C$11 * '1. Master Inputs'!$E$11)) * '3. Risk Simulation'!$B$6 -> 86486.4 | M6: =(L6*30)/100000 -> 25.94592 | N6: =M6-('1. Master Inputs'!F5*C6) -> 25.94592
A7: C6 | B7: South Plaza | C7: 1 | D7: 1 | E7: 4 | F7: =D7+E7 -> 5 | G7: ='1. Master Inputs'!E21*C7 -> 10 | H7: =(D7*'1. Master Inputs'!D10) + (E7*'1. Master Inputs'!D11) -> 360 | I7: ='1. Master Inputs'!D21*C7 -> 500 | J7: =(C7*'1. Master Inputs'!C21) + (D7*'1. Master Inputs'!B10) + (E7*'1. Master Inputs'!B11) -> 113 | K7: =(D7*'1. Master Inputs'!C10) + (E7*'1. Master Inputs'!C11) -> 128 | L7: =((D7 * '1. Master Inputs'!$C$10 * '1. Master Inputs'!$E$10) + (E7 * '1. Master Inputs'!$C$11 * '1. Master Inputs'!$E$11)) * '3. Risk Simulation'!$B$6 -> 34646.4 | M7: =(L7*30)/100000 -> 10.39392 | N7: =M7-('1. Master Inputs'!F6*C7) -> 10.39392
I9: Total CapEx: | J9: =SUM(J2:J7) -> 450 | M9: Total Profit: | N9: =SUM(N2:N7) -> 48.13344
A11: Zone | B11: Baseline Demand | C11: Active Sites <5km (E) | D11: Zone Covered? (Y) | E11: Covered Sessions
A12: Z1 | B12: 180 | C12: =C2+C4+C5 -> 1 | D12: 1 | E12: =B12*D12 -> 180
A13: Z2 | B13: 120 | C13: =C2+C3+C5 -> 1 | D13: 1 | E13: =B13*D13 -> 120
A14: Z3 | B14: 220 | C14: =C2+C4+C5 -> 1 | D14: 1 | E14: =B14*D14 -> 220
A15: Z4 | B15: 100 | C15: =C2+C3+C4+C5 -> 1 | D15: 1 | E15: =B15*D15 -> 100
A16: Z5 | B16: 160 | C16: =C4+C6+C7 -> 2 | D16: 1 | E16: =B16*D16 -> 160
A17: Z6 | B17: 140 | C17: =C6+C7 -> 2 | D17: 1 | E17: =B17*D17 -> 140
A19: Total Demand: | B19: =SUM(B12:B17)* '3. Risk Simulation'!$B$6 -> 993.6 | C19: Total Covered: | D19: =SUM(E12:E17) -> 920 | E19: Coverage %: | F19: =D19/B19 -> 0.92592593

Sheet 3. Risk Simulation
A1: A (Parameter) | B1: B (Value) | D1: Scenario | E1: Simulated Net Profit
A2: EV Adoption Growth (Low) | B2: 0.25 | E2: ='2. Optimization Engine'!N9 -> 48.13344 | G2: Average (Expected) Profit: | H2: =AVERAGE(E3:E1002) -> 44.538207
A3: EV Adoption Growth (High) | B3: 0.25 | D3: 1 | E3: ='2. Optimization Engine'!$N$9 * (1 + (RAND()-0.5)*0.5) -> 49.629469 | G3: Worst-Case Profit (5th Percentile) | H3: =PERCENTILE(E3:E1002, 0.05) -> 30.549317
A4: Session Length Variance | B4: 0.15 | D4: 2 | E4: 35.038304 | G4: Best-Case Profit (95th Percentile) | H4: =PERCENTILE(E3:E1002, 0.95) -> 60.450983
A5: Grid Failure Probability | B5: 0.06 | D5: 3 | E5: 41.593387 | G5: Probability of Loss: | H5: =COUNTIF(E3:E1002, "<0")/1000 -> 0
A6: Live Demand Multiplier: | B6: =1+RANDBETWEEN(-25, 25)/100 -> 1.08 | D6: 4 | E6: 38.515965
D7: 5 | E7: 34.551685
D8: 6 | E8: 49.443311
D9: 7 | E9: 38.304747
D10: 8 | E10: 32.334605
D11: 9 | E11: 31.063683
D12: 10 | E12: 53.616337
D13: 11 | E13: 48.858042
D14: 12 | E14: 55.323931
D15: 13 | E15: 44.478811
D16: 14 | E16: 44.482794
D17: 15 | E17: 36.920476
D18: 16 | E18: 35.71956
... D1004: 1002 | E1004: 49.196909
